<?xml version="1.0" encoding="utf-8"?>
<!-- Version 0.4.1 from github.com/frankaemika/franka_ros/franka_description -->
<robot xmlns:xacro="http://www.ros.org/wiki/xacro" name="gripper">
  <xacro:macro name="gripper" params="connected_to:='' ns:='' rpy:='0 0 0' xyz:='0 0 0' ">
    <xacro:unless value="${connected_to == ''}">
      <joint name="${ns}_gripper_joint" type="fixed">
        <parent link="${connected_to}"/>
        <child link="${ns}_hand"/>
        <origin xyz="${xyz}" rpy="${rpy}"/>
      </joint>
    </xacro:unless>
    <link name="${ns}_hand">
      <visual>
        <geometry>
          <!-- mesh filename="package://cobot_description/meshes/visual/hand.dae"/ -->
          <mesh filename="package://cobot_description/meshes/gripper/CLAW-BASE-REVISED.stl"/>
        </geometry>
	<material name="">
          <color rgba="0.9 0.9 0.9 1" />
	</material>
      </visual>
      <collision>
        <geometry>
          <!-- mesh filename="package://cobot_description/meshes/collision/hand.stl"/ -->
          <mesh filename="package://cobot_description/meshes/gripper/CLAW-BASE-REVISED.stl"/>   
        </geometry>
      </collision>
    </link>
    <link name="${ns}_leftfinger">
      <visual>
        <geometry>
          <mesh filename="package://cobot_description/meshes/gripper/CLAW-FINGER-REVISED.stl"/>
        </geometry>
        <material name="">
          <color rgba="0 0.63 0 1" />
	</material>
      </visual>
      <collision>
        <geometry>
          <mesh filename="package://cobot_description/meshes/gripper/CLAW-FINGER-REVISED.stl"/>
        </geometry>
      </collision>
    </link>
    <link name="${ns}_rightfinger">
      <visual>
        <origin xyz="0 0 0" rpy="0 0 ${pi}"/>
        <geometry>
          <mesh filename="package://cobot_description/meshes/gripper/CLAW-FINGER-REVISED.stl"/>
        </geometry>
        <material name="">
          <color rgba="0 0.63 0 1" />
	</material>
      </visual>
      <collision>
        <origin xyz="0 0 0" rpy="0 0 ${pi}"/>
        <geometry>
          <mesh filename="package://cobot_description/meshes/gripper/CLAW-FINGER-REVISED.stl"/>
        </geometry>
      </collision>
    </link>
    <joint name="${ns}_finger_joint1" type="prismatic">
      <parent link="${ns}_hand"/>
      <child link="${ns}_leftfinger"/>
      <!-- origin xyz="0 0 0.0584" rpy="0 0 0"/ -->
      <origin xyz="0 0.019 0.128" rpy="0 0 0"/>
      <!-- axis xyz="0 1 0"/ -->
      <axis xyz="0 1 -1.5"/>
      <!-- limit effort="20" lower="0.0" upper="0.04" velocity="0.2"/ -->
      <limit effort="20" lower="0.0" upper="0.08" velocity="0.2"/>
    </joint>
    <joint name="${ns}_finger_joint2" type="prismatic">
      <parent link="${ns}_hand"/>
      <child link="${ns}_rightfinger"/>
      <!-- origin xyz="0 0 0.0584" rpy="0 0 0"/ -->
      <origin xyz="0 -0.019 0.128" rpy="0 0 0"/>
      <!-- axis xyz="0 -1 0"/  -->
      <axis xyz="0 -1 -1.5"/>
      <!-- limit effort="20" lower="0.0" upper="0.04" velocity="0.2"/ -->
      <limit effort="20" lower="0.0" upper="0.08" velocity="0.2"/>
      <!--mimic joint="${ns}_finger_joint1" /-->
    </joint>
  </xacro:macro>
</robot>
